<?xml version="1.0" encoding="utf-8"?>
<!-- This URDF was automatically created by SolidWorks to URDF Exporter! Originally created by Stephen Brawner (brawner@gmail.com) 
     Commit Version: 1.6.0-4-g7f85cfe  Build Version: 1.6.7995.38578
     For more information, please see http://wiki.ros.org/sw_urdf_exporter -->
<robot
  name="A1_description">
  <link
    name="base_footprint">
    <inertial>
      <origin
        xyz="0 0 0"
        rpy="0 0 0" />
      <mass
        value="0" />
      <inertia
        ixx="0"
        ixy="0"
        ixz="0"
        iyy="0"
        iyz="0"
        izz="0" />
    </inertial>
  </link>
  <joint
    name="world_to_base"
    type="fixed">
    <origin
      xyz="0 0 0"
      rpy="0 0 3.14159265359" />
    <parent
      link="base_footprint" />
    <child
      link="base_link" />
  </joint>
  <link
    name="base_link">
    <inertial>
      <origin
        xyz="0.00101552858041876 -1.23050644189604E-05 0.0492338256278236"
        rpy="0 0 0" />
      <mass
        value="0.303146304961026" />
      <inertia
        ixx="0.000229422866993753"
        ixy="-2.66559260806856E-10"
        ixz="8.08919655194803E-08"
        iyy="0.000232399980656072"
        iyz="9.11524933608658E-11"
        izz="0.000444426560442023" />
    </inertial>
    <visual>
      <origin
        xyz="0 0 0"
        rpy="0 0 0" />
      <geometry>
        <mesh
          filename="package://A1_description/meshes/base_link.STL" />
      </geometry>
      <material
        name="">
        <color
          rgba="1 1 0 1" />
      </material>
    </visual>
    <collision>
      <origin
        xyz="0 0 0"
        rpy="0 0 0" />
      <geometry>
        <mesh
          filename="package://A1_description/meshes/base_link.STL" />
      </geometry>
    </collision>
  </link>
  <link
    name="link1">
    <inertial>
      <origin
        xyz="-0.00242389712204533 -1.33133821402787E-05 -5.22236721844926E-06"
        rpy="0 0 0" />
      <mass
        value="0.258047338437728" />
      <inertia
        ixx="0.000392638333383343"
        ixy="2.92195112785068E-08"
        ixz="-1.47633422254501E-10"
        iyy="0.000200318680837016"
        iyz="3.80699591407616E-10"
        izz="0.000204628596173256" />
    </inertial>
    <visual>
      <origin
        xyz="0 0 0"
        rpy="0 0 0" />
      <geometry>
        <mesh
          filename="package://A1_description/meshes/link1.STL" />
      </geometry>
      <material
        name="">
        <color
          rgba="1 1 1 1" />
      </material>
    </visual>
    <collision>
      <origin
        xyz="0 0 0"
        rpy="0 0 0" />
      <geometry>
        <mesh
          filename="package://A1_description/meshes/link1.STL" />
      </geometry>
    </collision>
  </link>
  <joint
    name="joint1"
    type="revolute">
    <origin
      xyz="3.7894E-05 -3.7894E-05 0.065"
      rpy="3.1416 -1.5708 0" />
    <parent
      link="base_link" />
    <child
      link="link1" />
    <axis
      xyz="1 0 0" />
    <limit
      lower="-2.6179"
      upper="2.6179"
      effort="1"
      velocity="1" />
  </joint>
  <link
    name="link2">
    <inertial>
      <origin
        xyz="0.0559779522682743 0.0277713643302713 -1.33226762955019E-15"
        rpy="0 0 0" />
      <mass
        value="0.0292941676126594" />
      <inertia
        ixx="1.0098871364547E-05"
        ixy="1.48048521746688E-19"
        ixz="-6.46457070693473E-21"
        iyy="6.24776323259193E-06"
        iyz="-1.46947601798089E-21"
        izz="1.2676334069482E-05" />
    </inertial>
    <visual>
      <origin
        xyz="0 0 0"
        rpy="0 0 0" />
      <geometry>
        <mesh
          filename="package://A1_description/meshes/link2.STL" />
      </geometry>
      <material
        name="">
        <color
          rgba="0.149019607843137 0.149019607843137 0.149019607843137 1" />
      </material>
    </visual>
    <collision>
      <origin
        xyz="0 0 0"
        rpy="0 0 0" />
      <geometry>
        <mesh
          filename="package://A1_description/meshes/link2.STL" />
      </geometry>
    </collision>
  </link>
  <joint
    name="joint2"
    type="revolute">
    <origin
      xyz="0.0384011585138843 -0.0280427286607554 0.000112794652719517"
      rpy="0 0 0" />
    <parent
      link="link1" />
    <child
      link="link2" />
    <axis
      xyz="0 -1 0" />
    <limit
      lower="-1.5707"
      upper="1.5707"
      effort="1"
      velocity="1" />
  </joint>
  <link
    name="link3">
    <inertial>
      <origin
        xyz="0.0435807988520146 -0.0275938137640814 0.000897639461304722"
        rpy="0 0 0" />
      <mass
        value="0.07324048600557" />
      <inertia
        ixx="1.42342228458047E-05"
        ixy="-1.40703445398905E-12"
        ixz="-2.95266844703855E-10"
        iyy="1.44156892978549E-05"
        iyz="9.12662435471617E-21"
        izz="2.36438636238762E-05" />
    </inertial>
    <visual>
      <origin
        xyz="0 0 0"
        rpy="0 0 0" />
      <geometry>
        <mesh
          filename="package://A1_description/meshes/link3.STL" />
      </geometry>
      <material
        name="">
        <color
          rgba="0.250980392156863 0.250980392156863 0.250980392156863 1" />
      </material>
    </visual>
    <collision>
      <origin
        xyz="0 0 0"
        rpy="0 0 0" />
      <geometry>
        <mesh
          filename="package://A1_description/meshes/link3.STL" />
      </geometry>
    </collision>
  </link>
  <joint
    name="joint3"
    type="revolute">
    <origin
      xyz="0.10506969244116 0.0555213643303918 0"
      rpy="0 0 0" />
    <parent
      link="link2" />
    <child
      link="link3" />
    <axis
      xyz="0 1 0" />
    <limit
      lower="-2.268861111"
      upper="2.268861111"
      effort="1"
      velocity="1" />
  </joint>
  <link
    name="link4">
    <inertial>
      <origin
        xyz="0.0446657818355911 -0.0271205621084167 -0.00906240843022377"
        rpy="0 0 0" />
      <mass
        value="0.0381126564083311" />
      <inertia
        ixx="7.48254504589362E-06"
        ixy="3.80699591465632E-10"
        ixz="5.11195698063154E-07"
        iyy="1.25421846509825E-05"
        iyz="1.47633422330827E-10"
        izz="1.05051567305746E-05" />
    </inertial>
    <visual>
      <origin
        xyz="0 0 0"
        rpy="0 0 0" />
      <geometry>
        <mesh
          filename="package://A1_description/meshes/link4.STL" />
      </geometry>
      <material
        name="">
        <color
          rgba="0.250980392156863 0.250980392156863 0.250980392156863 1" />
      </material>
    </visual>
    <collision>
      <origin
        xyz="0 0 0"
        rpy="0 0 0" />
      <geometry>
        <mesh
          filename="package://A1_description/meshes/link4.STL" />
      </geometry>
    </collision>
  </link>
  <joint
    name="joint4"
    type="revolute">
    <origin
      xyz="0.0871615977040367 -0.000500000000001943 0.000311127984646831"
      rpy="0 0 0" />
    <parent
      link="link3" />
    <child
      link="link4" />
    <axis
      xyz="0 -1 0" />
    <limit
      lower="-2.443388889"
      upper="2.443388889"
      effort="1"
      velocity="1" />
  </joint>
  <link
    name="link5">
    <inertial>
      <origin
        xyz="0.0317799388191369 -0.00293083767543667 -0.0145095022099833"
        rpy="0 0 0" />
      <mass
        value="0.0455072301968907" />
      <inertia
        ixx="9.9849446696972E-06"
        ixy="-2.66504713989686E-09"
        ixz="-9.1152493354193E-11"
        iyy="7.60846958311746E-06"
        iyz="8.08919655194885E-08"
        izz="9.09220227722319E-06" />
    </inertial>
    <visual>
      <origin
        xyz="0 0 0"
        rpy="0 0 0" />
      <geometry>
        <mesh
          filename="package://A1_description/meshes/link5.STL" />
      </geometry>
      <material
        name="">
        <color
          rgba="0.196078431372549 0.196078431372549 0.196078431372549 1" />
      </material>
    </visual>
    <collision>
      <origin
        xyz="0 0 0"
        rpy="0 0 0" />
      <geometry>
        <mesh
          filename="package://A1_description/meshes/link5.STL" />
      </geometry>
    </collision>
  </link>
  <joint
    name="joint5"
    type="revolute">
    <origin
      xyz="0.0712499999999997 -0.0272500000000622 0"
      rpy="0 0 0" />
    <parent
      link="link4" />
    <child
      link="link5" />
    <axis
      xyz="1 0 0" />
    <limit
      lower="-2.356125"
      upper="2.356125"
      effort="1"
      velocity="1" />
  </joint>
  <link
    name="link6">
    <inertial>
      <origin
        xyz="0.1 0 0"
        rpy="0 0 0" />
      <mass
        value="0.01" />
      <inertia
        ixx="1e-6"
        ixy="0"
        ixz="0"
        iyy="1e-6"
        iyz="0"
        izz="1e-6" />
    </inertial>
    <visual>
      <origin
        xyz="0 0 0"
        rpy="0 0 0" />
      <geometry>
        <box size="0.05 0.05 0.05"/>
      </geometry>
      <material name="">
        <color rgba="0.5 0.5 1 1"/>
      </material>
    </visual>
    <collision>
      <origin
        xyz="0 0 0"
        rpy="0 0 0" />
      <geometry>
        <box size="0.05 0.05 0.05"/>
      </geometry>
    </collision>
  </link>
  <joint
    name="joint6"
    type="revolute">
    <origin
      xyz="0.095 0 0"
      rpy="0 0 0" />
    <parent
      link="link5" />
    <child
      link="link6" />
    <axis
      xyz="0 1 0" />
    <limit
      lower="-0.05"
      upper="0.05"
      effort="1"
      velocity="1" />
  </joint>
  <link
    name="camera_link">
    <inertial>
      <origin
        xyz="0 0 0"
        rpy="0 0 0" />
      <mass
        value="0.02" />
      <inertia
        ixx="1e-6"
        ixy="0"
        ixz="0"
        iyy="1e-6"
        iyz="0"
        izz="1e-6" />
    </inertial>
    <visual>
      <origin
        xyz="0 0 0"
        rpy="0 0 0" />
      <geometry>
        <box size="0.01 0.03 0.03"/>
      </geometry>
      <material name="">
        <color rgba="0.2 0.2 0.2 1"/>
      </material>
    </visual>
    <collision>
      <origin
        xyz="0 0 0"
        rpy="0 0 0" />
      <geometry>
        <box size="0.01 0.03 0.03"/>
      </geometry>
    </collision>
  </link>
  <joint
    name="camera_joint"
    type="fixed">
    <origin
      xyz="-0.005 0 0.05"
      rpy="0 0 0" />
    <parent
      link="link5" />
    <child
      link="camera_link" />
  </joint>
</robot>

